[32m2024-04-04 20:17:42 -0500[0m - dagster - [34mDEBUG[0m - __ASSET_JOB - 73213f95-a06e-43e2-bb8f-12abf2ebdd2b - 50316 - LOGS_CAPTURED - Started capturing logs in process (pid: 50316).
[32m2024-04-04 20:17:42 -0500[0m - dagster - [34mDEBUG[0m - __ASSET_JOB - 73213f95-a06e-43e2-bb8f-12abf2ebdd2b - 50316 - ncaa_cleaned - STEP_START - Started execution of step "ncaa_cleaned".
[32m2024-04-04 20:17:42 -0500[0m - dagster - [34mERROR[0m - [31m__ASSET_JOB - 73213f95-a06e-43e2-bb8f-12abf2ebdd2b - 50316 - ncaa_cleaned - STEP_FAILURE - Execution of step "ncaa_cleaned" failed.

dagster._core.errors.DagsterExecutionStepExecutionError: Error occurred while executing op "ncaa_cleaned"::

ValueError: Expected a 1D array, got an array with shape (7046, 2)

Stack Trace:
  File "/Users/isaacanderson/anaconda3/envs/boo/lib/python3.12/site-packages/dagster/_core/execution/plan/utils.py", line 54, in op_execution_error_boundary
    yield
  File "/Users/isaacanderson/anaconda3/envs/boo/lib/python3.12/site-packages/dagster/_utils/__init__.py", line 463, in iterate_with_context
    next_output = next(iterator)
                  ^^^^^^^^^^^^^^
  File "/Users/isaacanderson/anaconda3/envs/boo/lib/python3.12/site-packages/dagster/_core/execution/plan/compute_generator.py", line 131, in _coerce_op_compute_fn_to_iterator
    result = invoke_compute_fn(
             ^^^^^^^^^^^^^^^^^^
  File "/Users/isaacanderson/anaconda3/envs/boo/lib/python3.12/site-packages/dagster/_core/execution/plan/compute_generator.py", line 125, in invoke_compute_fn
    return fn(context, **args_to_pass) if context_arg_provided else fn(**args_to_pass)
                                                                    ^^^^^^^^^^^^^^^^^^
  File "/Users/isaacanderson/Desktop/CSE314/MarchMadness/projectDag/projectDag/assets/ETL/__init__.py", line 22, in ncaa_cleaned
    df = c.clean_data(df)
         ^^^^^^^^^^^^^^^^
  File "/Users/isaacanderson/anaconda3/envs/boo/lib/python3.12/site-packages/ncaa_mod/cleaning.py", line 55, in clean_data
    df = create_made_postseason(df)
         ^^^^^^^^^^^^^^^^^^^^^^^^^^
  File "/Users/isaacanderson/anaconda3/envs/boo/lib/python3.12/site-packages/ncaa_mod/cleaning.py", line 48, in create_made_postseason
    df['MADE_POSTSEASON'] = np.where(pd.isna(df['POSTSEASON']), 0, 1)
    ~~^^^^^^^^^^^^^^^^^^^
  File "/Users/isaacanderson/anaconda3/envs/boo/lib/python3.12/site-packages/pandas/core/frame.py", line 3950, in __setitem__
    self._set_item(key, value)
  File "/Users/isaacanderson/anaconda3/envs/boo/lib/python3.12/site-packages/pandas/core/frame.py", line 4156, in _set_item
    self._set_item_mgr(key, value)
  File "/Users/isaacanderson/anaconda3/envs/boo/lib/python3.12/site-packages/pandas/core/frame.py", line 4113, in _set_item_mgr
    self._mgr.insert(len(self._info_axis), key, value)
  File "/Users/isaacanderson/anaconda3/envs/boo/lib/python3.12/site-packages/pandas/core/internals/managers.py", line 1403, in insert
    raise ValueError(

The above exception occurred during handling of the following exception:
KeyError: 'MADE_POSTSEASON'

Stack Trace:
  File "/Users/isaacanderson/anaconda3/envs/boo/lib/python3.12/site-packages/pandas/core/frame.py", line 4110, in _set_item_mgr
    loc = self._info_axis.get_loc(key)
          ^^^^^^^^^^^^^^^^^^^^^^^^^^^^
  File "/Users/isaacanderson/anaconda3/envs/boo/lib/python3.12/site-packages/pandas/core/indexes/base.py", line 3655, in get_loc
    raise KeyError(key) from err

The above exception was caused by the following exception:
KeyError: 'MADE_POSTSEASON'

Stack Trace:
  File "/Users/isaacanderson/anaconda3/envs/boo/lib/python3.12/site-packages/pandas/core/indexes/base.py", line 3653, in get_loc
    return self._engine.get_loc(casted_key)
           ^^^^^^^^^^^^^^^^^^^^^^^^^^^^^^^^
  File "pandas/_libs/index.pyx", line 147, in pandas._libs.index.IndexEngine.get_loc
  File "pandas/_libs/index.pyx", line 171, in pandas._libs.index.IndexEngine.get_loc
  File "pandas/_libs/index.pyx", line 214, in pandas._libs.index.IndexEngine._get_loc_duplicates
  File "pandas/_libs/index.pyx", line 222, in pandas._libs.index.IndexEngine._maybe_get_bool_indexer
  File "pandas/_libs/index.pyx", line 114, in pandas._libs.index._unpack_bool_indexer
[0m
