[32m2024-04-23 16:13:12 -0500[0m - dagster - [34mDEBUG[0m - __ASSET_JOB - dc5208a5-eb45-43af-b2e5-0be8a3fe040e - 68795 - LOGS_CAPTURED - Started capturing logs in process (pid: 68795).
[32m2024-04-23 16:13:12 -0500[0m - dagster - [34mDEBUG[0m - __ASSET_JOB - dc5208a5-eb45-43af-b2e5-0be8a3fe040e - 68795 - predictionValidation - STEP_START - Started execution of step "predictionValidation".
[32m2024-04-23 16:13:12 -0500[0m - dagster - [34mDEBUG[0m - __ASSET_JOB - dc5208a5-eb45-43af-b2e5-0be8a3fe040e - predictionValidation - Loading file from: /Users/isaacanderson/Desktop/CSE314/MarchMadness/projectDag/tmpf7gyw7w9/storage/bubbleClassification using PickledObjectFilesystemIOManager...
[32m2024-04-23 16:13:12 -0500[0m - dagster - [34mDEBUG[0m - __ASSET_JOB - dc5208a5-eb45-43af-b2e5-0be8a3fe040e - 68795 - predictionValidation - ASSET_OBSERVATION - DagsterEventType.ASSET_OBSERVATION for step predictionValidation
[32m2024-04-23 16:13:12 -0500[0m - dagster - [34mDEBUG[0m - __ASSET_JOB - dc5208a5-eb45-43af-b2e5-0be8a3fe040e - 68795 - predictionValidation - LOADED_INPUT - Loaded input "bubbleClassification" using input manager "io_manager"
[32m2024-04-23 16:13:12 -0500[0m - dagster - [34mDEBUG[0m - __ASSET_JOB - dc5208a5-eb45-43af-b2e5-0be8a3fe040e - 68795 - predictionValidation - STEP_INPUT - Got input "bubbleClassification" of type "Any". (Type check passed).
[32m2024-04-23 16:13:12 -0500[0m - dagster - [34mERROR[0m - [31m__ASSET_JOB - dc5208a5-eb45-43af-b2e5-0be8a3fe040e - 68795 - predictionValidation - STEP_FAILURE - Execution of step "predictionValidation" failed.

dagster._core.errors.DagsterExecutionStepExecutionError: Error occurred while executing op "predictionValidation"::

KeyError: 'MADE_POSTSEASON'

Stack Trace:
  File "/Users/isaacanderson/anaconda3/envs/boo/lib/python3.12/site-packages/dagster/_core/execution/plan/utils.py", line 54, in op_execution_error_boundary
    yield
  File "/Users/isaacanderson/anaconda3/envs/boo/lib/python3.12/site-packages/dagster/_utils/__init__.py", line 464, in iterate_with_context
    next_output = next(iterator)
                  ^^^^^^^^^^^^^^
  File "/Users/isaacanderson/anaconda3/envs/boo/lib/python3.12/site-packages/dagster/_core/execution/plan/compute_generator.py", line 141, in _coerce_op_compute_fn_to_iterator
    result = invoke_compute_fn(
             ^^^^^^^^^^^^^^^^^^
  File "/Users/isaacanderson/anaconda3/envs/boo/lib/python3.12/site-packages/dagster/_core/execution/plan/compute_generator.py", line 129, in invoke_compute_fn
    return fn(context, **args_to_pass) if context_arg_provided else fn(**args_to_pass)
                                                                    ^^^^^^^^^^^^^^^^^^
  File "/Users/isaacanderson/Desktop/CSE314/MarchMadness/projectDag/projectDag/assets/ETL/__init__.py", line 64, in predictionValidation
    accuracy = (validation['Prediction'] == validation['MADE_POSTSEASON']).mean()
                                            ~~~~~~~~~~^^^^^^^^^^^^^^^^^^^
  File "/Users/isaacanderson/anaconda3/envs/boo/lib/python3.12/site-packages/pandas/core/frame.py", line 4090, in __getitem__
    indexer = self.columns.get_loc(key)
              ^^^^^^^^^^^^^^^^^^^^^^^^^
  File "/Users/isaacanderson/anaconda3/envs/boo/lib/python3.12/site-packages/pandas/core/indexes/base.py", line 3812, in get_loc
    raise KeyError(key) from err

The above exception was caused by the following exception:
KeyError: 'MADE_POSTSEASON'

Stack Trace:
  File "/Users/isaacanderson/anaconda3/envs/boo/lib/python3.12/site-packages/pandas/core/indexes/base.py", line 3805, in get_loc
    return self._engine.get_loc(casted_key)
           ^^^^^^^^^^^^^^^^^^^^^^^^^^^^^^^^
  File "index.pyx", line 167, in pandas._libs.index.IndexEngine.get_loc
  File "index.pyx", line 196, in pandas._libs.index.IndexEngine.get_loc
  File "pandas/_libs/hashtable_class_helper.pxi", line 7081, in pandas._libs.hashtable.PyObjectHashTable.get_item
  File "pandas/_libs/hashtable_class_helper.pxi", line 7089, in pandas._libs.hashtable.PyObjectHashTable.get_item
[0m
