[32m2024-04-23 14:35:05 -0500[0m - dagster - [34mDEBUG[0m - __ASSET_JOB - 0f137bb8-20d4-4533-a176-10a5e8370c43 - 43889 - LOGS_CAPTURED - Started capturing logs in process (pid: 43889).
[32m2024-04-23 14:35:05 -0500[0m - dagster - [34mDEBUG[0m - __ASSET_JOB - 0f137bb8-20d4-4533-a176-10a5e8370c43 - 43889 - ncaa_cleaned - STEP_START - Started execution of step "ncaa_cleaned".
[32m2024-04-23 14:35:05 -0500[0m - dagster - [34mDEBUG[0m - __ASSET_JOB - 0f137bb8-20d4-4533-a176-10a5e8370c43 - ncaa_cleaned - Loading file from: /Users/isaacanderson/Desktop/CSE314/MarchMadness/projectDag/tmprc4x5hfk/storage/ncaa_rankings using PickledObjectFilesystemIOManager...
[32m2024-04-23 14:35:05 -0500[0m - dagster - [34mDEBUG[0m - __ASSET_JOB - 0f137bb8-20d4-4533-a176-10a5e8370c43 - 43889 - ncaa_cleaned - ASSET_OBSERVATION - DagsterEventType.ASSET_OBSERVATION for step ncaa_cleaned
[32m2024-04-23 14:35:05 -0500[0m - dagster - [34mDEBUG[0m - __ASSET_JOB - 0f137bb8-20d4-4533-a176-10a5e8370c43 - 43889 - ncaa_cleaned - LOADED_INPUT - Loaded input "ncaa_rankings" using input manager "io_manager", from output "result" of step "ncaa_rankings"
[32m2024-04-23 14:35:05 -0500[0m - dagster - [34mDEBUG[0m - __ASSET_JOB - 0f137bb8-20d4-4533-a176-10a5e8370c43 - 43889 - ncaa_cleaned - STEP_INPUT - Got input "ncaa_rankings" of type "Any". (Type check passed).
[32m2024-04-23 14:35:05 -0500[0m - dagster - [34mERROR[0m - [31m__ASSET_JOB - 0f137bb8-20d4-4533-a176-10a5e8370c43 - 43889 - ncaa_cleaned - STEP_FAILURE - Execution of step "ncaa_cleaned" failed.

dagster._core.errors.DagsterExecutionStepExecutionError: Error occurred while executing op "ncaa_cleaned"::

ValueError: Expected a 1D array, got an array with shape (3885, 2)

Stack Trace:
  File "/Users/isaacanderson/anaconda3/envs/boo/lib/python3.12/site-packages/dagster/_core/execution/plan/utils.py", line 54, in op_execution_error_boundary
    yield
  File "/Users/isaacanderson/anaconda3/envs/boo/lib/python3.12/site-packages/dagster/_utils/__init__.py", line 464, in iterate_with_context
    next_output = next(iterator)
                  ^^^^^^^^^^^^^^
  File "/Users/isaacanderson/anaconda3/envs/boo/lib/python3.12/site-packages/dagster/_core/execution/plan/compute_generator.py", line 141, in _coerce_op_compute_fn_to_iterator
    result = invoke_compute_fn(
             ^^^^^^^^^^^^^^^^^^
  File "/Users/isaacanderson/anaconda3/envs/boo/lib/python3.12/site-packages/dagster/_core/execution/plan/compute_generator.py", line 129, in invoke_compute_fn
    return fn(context, **args_to_pass) if context_arg_provided else fn(**args_to_pass)
                                                                    ^^^^^^^^^^^^^^^^^^
  File "/Users/isaacanderson/Desktop/CSE314/MarchMadness/projectDag/projectDag/assets/ETL/__init__.py", line 33, in ncaa_cleaned
    df = c.clean_data(ncaa_rankings)
         ^^^^^^^^^^^^^^^^^^^^^^^^^^^
  File "/Users/isaacanderson/Desktop/CSE314/MarchMadness/ncaa_mod/cleaning.py", line 55, in clean_data
    df = create_made_postseason(df)
         ^^^^^^^^^^^^^^^^^^^^^^^^^^
  File "/Users/isaacanderson/Desktop/CSE314/MarchMadness/ncaa_mod/cleaning.py", line 47, in create_made_postseason
    df['MADE_POSTSEASON'] = np.where(pd.isna(df['POSTSEASON']), 0, 1)
    ~~^^^^^^^^^^^^^^^^^^^
  File "/Users/isaacanderson/anaconda3/envs/boo/lib/python3.12/site-packages/pandas/core/frame.py", line 4299, in __setitem__
    self._set_item(key, value)
  File "/Users/isaacanderson/anaconda3/envs/boo/lib/python3.12/site-packages/pandas/core/frame.py", line 4526, in _set_item
    self._set_item_mgr(key, value, refs)
  File "/Users/isaacanderson/anaconda3/envs/boo/lib/python3.12/site-packages/pandas/core/frame.py", line 4476, in _set_item_mgr
    self._mgr.insert(len(self._info_axis), key, value, refs)
  File "/Users/isaacanderson/anaconda3/envs/boo/lib/python3.12/site-packages/pandas/core/internals/managers.py", line 1370, in insert
    raise ValueError(

The above exception occurred during handling of the following exception:
KeyError: 'MADE_POSTSEASON'

Stack Trace:
  File "/Users/isaacanderson/anaconda3/envs/boo/lib/python3.12/site-packages/pandas/core/frame.py", line 4473, in _set_item_mgr
    loc = self._info_axis.get_loc(key)
          ^^^^^^^^^^^^^^^^^^^^^^^^^^^^
  File "/Users/isaacanderson/anaconda3/envs/boo/lib/python3.12/site-packages/pandas/core/indexes/base.py", line 3812, in get_loc
    raise KeyError(key) from err

The above exception was caused by the following exception:
KeyError: 'MADE_POSTSEASON'

Stack Trace:
  File "/Users/isaacanderson/anaconda3/envs/boo/lib/python3.12/site-packages/pandas/core/indexes/base.py", line 3805, in get_loc
    return self._engine.get_loc(casted_key)
           ^^^^^^^^^^^^^^^^^^^^^^^^^^^^^^^^
  File "index.pyx", line 167, in pandas._libs.index.IndexEngine.get_loc
  File "index.pyx", line 191, in pandas._libs.index.IndexEngine.get_loc
  File "index.pyx", line 234, in pandas._libs.index.IndexEngine._get_loc_duplicates
  File "index.pyx", line 242, in pandas._libs.index.IndexEngine._maybe_get_bool_indexer
  File "index.pyx", line 134, in pandas._libs.index._unpack_bool_indexer
[0m
