[32m2024-04-23 14:17:17 -0500[0m - dagster - [34mDEBUG[0m - __ASSET_JOB - 7821cc5c-c2d7-43b9-b9a7-8dbe693ec58d - 31128 - LOGS_CAPTURED - Started capturing logs in process (pid: 31128).
[32m2024-04-23 14:17:17 -0500[0m - dagster - [34mDEBUG[0m - __ASSET_JOB - 7821cc5c-c2d7-43b9-b9a7-8dbe693ec58d - 31128 - bubble_chart - STEP_START - Started execution of step "bubble_chart".
[32m2024-04-23 14:17:17 -0500[0m - dagster - [34mDEBUG[0m - __ASSET_JOB - 7821cc5c-c2d7-43b9-b9a7-8dbe693ec58d - bubble_chart - Loading file from: /Users/isaacanderson/Desktop/CSE314/MarchMadness/projectDag/tmprc4x5hfk/storage/vis_dataset using PickledObjectFilesystemIOManager...
[32m2024-04-23 14:17:17 -0500[0m - dagster - [34mDEBUG[0m - __ASSET_JOB - 7821cc5c-c2d7-43b9-b9a7-8dbe693ec58d - 31128 - bubble_chart - ASSET_OBSERVATION - DagsterEventType.ASSET_OBSERVATION for step bubble_chart
[32m2024-04-23 14:17:17 -0500[0m - dagster - [34mDEBUG[0m - __ASSET_JOB - 7821cc5c-c2d7-43b9-b9a7-8dbe693ec58d - 31128 - bubble_chart - LOADED_INPUT - Loaded input "vis_dataset" using input manager "io_manager"
[32m2024-04-23 14:17:17 -0500[0m - dagster - [34mDEBUG[0m - __ASSET_JOB - 7821cc5c-c2d7-43b9-b9a7-8dbe693ec58d - 31128 - bubble_chart - STEP_INPUT - Got input "vis_dataset" of type "DataFrame". (Type check passed).
[32m2024-04-23 14:17:17 -0500[0m - dagster - [34mERROR[0m - [31m__ASSET_JOB - 7821cc5c-c2d7-43b9-b9a7-8dbe693ec58d - 31128 - bubble_chart - STEP_FAILURE - Execution of step "bubble_chart" failed.

dagster._core.errors.DagsterExecutionStepExecutionError: Error occurred while executing op "bubble_chart"::

KeyError: 'W'

Stack Trace:
  File "/Users/isaacanderson/anaconda3/envs/boo/lib/python3.12/site-packages/dagster/_core/execution/plan/utils.py", line 54, in op_execution_error_boundary
    yield
  File "/Users/isaacanderson/anaconda3/envs/boo/lib/python3.12/site-packages/dagster/_utils/__init__.py", line 464, in iterate_with_context
    next_output = next(iterator)
                  ^^^^^^^^^^^^^^
  File "/Users/isaacanderson/anaconda3/envs/boo/lib/python3.12/site-packages/dagster/_core/execution/plan/compute_generator.py", line 141, in _coerce_op_compute_fn_to_iterator
    result = invoke_compute_fn(
             ^^^^^^^^^^^^^^^^^^
  File "/Users/isaacanderson/anaconda3/envs/boo/lib/python3.12/site-packages/dagster/_core/execution/plan/compute_generator.py", line 129, in invoke_compute_fn
    return fn(context, **args_to_pass) if context_arg_provided else fn(**args_to_pass)
                                                                    ^^^^^^^^^^^^^^^^^^
  File "/Users/isaacanderson/Desktop/CSE314/MarchMadness/projectDag/projectDag/assets/EDA/__init__.py", line 54, in bubble_chart
    fig = px.scatter(df_bubble, x="ADJOE", y="ADJDE", size= df_bubble['W'] * 100,
                                                           ~~~~~~~~~^^^^^
  File "/Users/isaacanderson/anaconda3/envs/boo/lib/python3.12/site-packages/pandas/core/frame.py", line 4090, in __getitem__
    indexer = self.columns.get_loc(key)
              ^^^^^^^^^^^^^^^^^^^^^^^^^
  File "/Users/isaacanderson/anaconda3/envs/boo/lib/python3.12/site-packages/pandas/core/indexes/base.py", line 3812, in get_loc
    raise KeyError(key) from err

The above exception was caused by the following exception:
KeyError: 'W'

Stack Trace:
  File "/Users/isaacanderson/anaconda3/envs/boo/lib/python3.12/site-packages/pandas/core/indexes/base.py", line 3805, in get_loc
    return self._engine.get_loc(casted_key)
           ^^^^^^^^^^^^^^^^^^^^^^^^^^^^^^^^
  File "index.pyx", line 167, in pandas._libs.index.IndexEngine.get_loc
  File "index.pyx", line 196, in pandas._libs.index.IndexEngine.get_loc
  File "pandas/_libs/hashtable_class_helper.pxi", line 7081, in pandas._libs.hashtable.PyObjectHashTable.get_item
  File "pandas/_libs/hashtable_class_helper.pxi", line 7089, in pandas._libs.hashtable.PyObjectHashTable.get_item
[0m
