[32m2024-04-05 00:15:59 -0500[0m - dagster - [34mDEBUG[0m - __ASSET_JOB - da392f72-947b-4ab2-a513-cf0b6e797155 - 41000 - LOGS_CAPTURED - Started capturing logs in process (pid: 41000).
[32m2024-04-05 00:15:59 -0500[0m - dagster - [34mDEBUG[0m - __ASSET_JOB - da392f72-947b-4ab2-a513-cf0b6e797155 - 41000 - eda - STEP_START - Started execution of step "eda".
[32m2024-04-05 00:16:06 -0500[0m - dagster - [34mERROR[0m - [31m__ASSET_JOB - da392f72-947b-4ab2-a513-cf0b6e797155 - 41000 - eda - STEP_FAILURE - Execution of step "eda" failed.

dagster._core.errors.DagsterExecutionStepExecutionError: Error occurred while executing op "eda"::

AttributeError: 'bytes' object has no attribute 'save'

Stack Trace:
  File "/Users/isaacanderson/anaconda3/envs/boo/lib/python3.12/site-packages/dagster/_core/execution/plan/utils.py", line 54, in op_execution_error_boundary
    yield
  File "/Users/isaacanderson/anaconda3/envs/boo/lib/python3.12/site-packages/dagster/_utils/__init__.py", line 463, in iterate_with_context
    next_output = next(iterator)
                  ^^^^^^^^^^^^^^
  File "/Users/isaacanderson/anaconda3/envs/boo/lib/python3.12/site-packages/dagster/_core/execution/plan/compute_generator.py", line 131, in _coerce_op_compute_fn_to_iterator
    result = invoke_compute_fn(
             ^^^^^^^^^^^^^^^^^^
  File "/Users/isaacanderson/anaconda3/envs/boo/lib/python3.12/site-packages/dagster/_core/execution/plan/compute_generator.py", line 125, in invoke_compute_fn
    return fn(context, **args_to_pass) if context_arg_provided else fn(**args_to_pass)
                                                                    ^^^^^^^^^^^^^^^^^^
  File "/Users/isaacanderson/Desktop/CSE314/MarchMadness/projectDag/projectDag/assets/ETL/__init__.py", line 50, in eda
    pio.to_image(fig, format="png", width=800, height=600, scale=2.0).save(buffer)
    ^^^^^^^^^^^^^^^^^^^^^^^^^^^^^^^^^^^^^^^^^^^^^^^^^^^^^^^^^^^^^^^^^^^^^^
[0m
